// Copyright (c) Microsoft Corporation.
// Licensed under the MIT License.

using System;
using System.Threading;
using System.Threading.Tasks;
using Microsoft.Coyote.Specifications;
using Xunit;
using Xunit.Abstractions;

namespace Microsoft.Coyote.BugFinding.Tests
{
    public class TaskWaitAllTests : BaseBugFindingTest
    {
        public TaskWaitAllTests(ITestOutputHelper output)
            : base(output)
        {
        }

        private static async Task WriteAsync(SharedEntry entry, int value)
        {
            await Task.CompletedTask;
            entry.Value = value;
        }

        private static async Task WriteWithDelayAsync(SharedEntry entry, int value)
        {
            await Task.Delay(1);
            entry.Value = value;
        }

        [Fact(Timeout = 5000)]
        public void TestWaitAllWithTwoSynchronousTasks()
        {
            this.TestWithError(() =>
            {
                SharedEntry entry = new SharedEntry();
                Task task1 = WriteAsync(entry, 5);
                Task task2 = WriteAsync(entry, 3);
                Task.WaitAll(task1, task2);
                AssertSharedEntryValue(entry, 5);
            },
            configuration: this.GetConfiguration().WithTestingIterations(200),
            expectedError: "Value is 3 instead of 5.",
            replay: true);
        }

        [Fact(Timeout = 5000)]
        public void TestWaitAllWithTwoAsynchronousTasks()
        {
            this.TestWithError(() =>
            {
                SharedEntry entry = new SharedEntry();
                Task task1 = WriteWithDelayAsync(entry, 3);
                Task task2 = WriteWithDelayAsync(entry, 5);
                Task.WaitAll(task1, task2);
                AssertSharedEntryValue(entry, 5);
            },
            configuration: this.GetConfiguration().WithTestingIterations(200),
            expectedError: "Value is 3 instead of 5.",
            replay: true);
        }

        [Fact(Timeout = 5000)]
        public void TestWaitAllWithTwoParallelTasks()
        {
            this.TestWithError(() =>
            {
                SharedEntry entry = new SharedEntry();

                Task task1 = Task.Run(async () =>
                {
                    await WriteAsync(entry, 3);
                });

                Task task2 = Task.Run(async () =>
                {
                    await WriteAsync(entry, 5);
                });

                Task.WaitAll(task1, task2);
                AssertSharedEntryValue(entry, 5);
            },
            configuration: this.GetConfiguration().WithTestingIterations(200),
            expectedError: "Value is 3 instead of 5.",
            replay: true);
        }

        [Fact(Timeout = 5000)]
        public void TestWaitAllWithTwoSynchronousTaskWithResults()
        {
            this.TestWithError(() =>
            {
                SharedEntry entry = new SharedEntry();
                Task<int> task1 = entry.GetWriteResultAsync(5);
                Task<int> task2 = entry.GetWriteResultAsync(3);
                Task.WaitAll(task1, task2);
                Specification.Assert(task1.Result == 5 && task2.Result is 3, "Found unexpected value.");
                Specification.Assert(task1.Result == task2.Result, "Results are not equal.");
            },
            configuration: this.GetConfiguration().WithTestingIterations(200),
            expectedError: "Results are not equal.",
            replay: true);
        }

        [Fact(Timeout = 5000)]
        public void TestWaitAllWithTwoAsynchronousTaskWithResults()
        {
            this.TestWithError(() =>
            {
                SharedEntry entry = new SharedEntry();
                Task<int> task1 = entry.GetWriteResultWithDelayAsync(5);
                Task<int> task2 = entry.GetWriteResultWithDelayAsync(3);
                Task.WaitAll(task1, task2);
                Specification.Assert(task1.Result == 5 && task2.Result is 3, "Found unexpected value.");
            },
            configuration: this.GetConfiguration().WithTestingIterations(200),
            expectedError: "Found unexpected value.",
            replay: true);
        }

        [Fact(Timeout = 5000)]
        public void TestWaitAllWithTwoParallelSynchronousTaskWithResults()
        {
            this.TestWithError(() =>
            {
                SharedEntry entry = new SharedEntry();

                Task<int> task1 = Task.Run(async () =>
                {
                    return await entry.GetWriteResultAsync(5);
                });

                Task<int> task2 = Task.Run(async () =>
                {
                    return await entry.GetWriteResultAsync(3);
                });

                Task.WaitAll(task1, task2);

                Specification.Assert(task1.Result == 5, $"The first task result is {task1.Result} instead of 5.");
                Specification.Assert(task2.Result is 3, $"The second task result is {task2.Result} instead of 3.");
                Specification.Assert(task1.Result == task2.Result, "Results are not equal.");
            },
            configuration: this.GetConfiguration().WithTestingIterations(200),
            expectedError: "Results are not equal.",
            replay: true);
        }

        [Fact(Timeout = 5000)]
        public void TestWaitAllWithTwoParallelAsynchronousTaskWithResults()
        {
            this.TestWithError(() =>
            {
                SharedEntry entry = new SharedEntry();

                Task<int> task1 = Task.Run(async () =>
                {
                    return await entry.GetWriteResultWithDelayAsync(5);
                });

                Task<int> task2 = Task.Run(async () =>
                {
                    return await entry.GetWriteResultWithDelayAsync(3);
                });

                Task.WaitAll(task1, task2);

                Specification.Assert(task1.Result == 5 && task2.Result is 3, "Found unexpected value.");
            },
            configuration: this.GetConfiguration().WithTestingIterations(200),
            expectedError: "Found unexpected value.",
            replay: true);
        }

        [Fact(Timeout = 5000)]
        public void TestWaitAllDeadlock()
        {
            this.TestWithError(async () =>
            {
                // Test that `WaitAll` deadlocks because one of the tasks cannot complete until later.
                var tcs = new TaskCompletionSource<bool>();
                Task.WaitAll(tcs.Task, Task.Delay(1));
                tcs.SetResult(true);
                await tcs.Task;
            },
            errorChecker: (e) =>
            {
                Assert.StartsWith("Deadlock detected.", e);
            },
            replay: true);
        }

        [Fact(Timeout = 5000)]
        public void TestWaitAllWithResultsAndDeadlock()
        {
            this.TestWithError(async () =>
            {
                // Test that `WaitAll` deadlocks because one of the tasks cannot complete until later.
                var tcs = new TaskCompletionSource<bool>();
                Task.WaitAll(tcs.Task, Task.FromResult(true));
                tcs.SetResult(true);
                await tcs.Task;
            },
            errorChecker: (e) =>
            {
                Assert.StartsWith("Deadlock detected.", e);
            },
            replay: true);
        }

        [Fact(Timeout = 5000)]
        public void TestWaitAllWithExceptionThrown()
        {
            this.TestWithException<InvalidOperationException>(() =>
            {
                Task[] tasks = new Task[1];
                tasks[0] = Task.Run(() =>
                {
                    throw new InvalidOperationException("Task failed.");
                });

                bool succeeded = false;
                Exception exception = null;
                try
                {
                    succeeded = Task.WaitAll(tasks, Timeout.Infinite);
                }
                catch (AggregateException e)
                {
                    exception = e.Flatten().InnerException;
                }

                Specification.Assert(!succeeded, "Waiting the task should not succeed.");
                Specification.Assert(tasks[0].Status is TaskStatus.Faulted, "The task is not faulted.");
                throw exception;
            },
            replay: true);
        }
    }
}
